<?xml version="1.0" encoding="utf-8"?>
<!-- This URDF was automatically created by SolidWorks to URDF Exporter! Originally created by Stephen Brawner (brawner@gmail.com) 
     Commit Version: 1.6.0-1-g15f4949  Build Version: 1.6.7594.29634
     For more information, please see http://wiki.ros.org/sw_urdf_exporter -->
<robot
  name="Solid_URDF">
  <link
    name="base_link">
    <inertial>
      <origin
        xyz="8.6736E-18 -4.5379E-18 0.021134"
        rpy="0 0 0" />
      <mass
        value="0.51331" />
      <inertia
        ixx="0.00058904"
        ixy="-2.8124E-20"
        ixz="7.919E-21"
        iyy="0.00058904"
        iyz="-3.3396E-20"
        izz="0.00099809" />
    </inertial>
    <visual>
      <origin
        xyz="0 0 0"
        rpy="0 0 0" />
      <geometry>
        <mesh
          filename="package://Solid_URDF/meshes/base_link.STL" />
      </geometry>
      <material
        name="">
        <color
          rgba="0.79216 0.81961 0.93333 1" />
      </material>
    </visual>
    <collision>
      <origin
        xyz="0 0 0"
        rpy="0 0 0" />
      <geometry>
        <mesh
          filename="package://Solid_URDF/meshes/base_link.STL" />
      </geometry>
    </collision>
  </link>
  <link
    name="Link_2">
    <inertial>
      <origin
        xyz="-1.7347E-18 1.1281E-08 0.058542"
        rpy="0 0 0" />
      <mass
        value="0.029815" />
      <inertia
        ixx="5.2832E-06"
        ixy="3.0433E-23"
        ixz="1.5486E-22"
        iyy="6.1777E-06"
        iyz="-4.16E-12"
        izz="4.8276E-06" />
    </inertial>
    <visual>
      <origin
        xyz="0 0 0"
        rpy="0 0 0" />
      <geometry>
        <mesh
          filename="package://Solid_URDF/meshes/Link_2.STL" />
      </geometry>
      <material
        name="">
        <color
          rgba="0.79216 0.81961 0.93333 1" />
      </material>
    </visual>
    <collision>
      <origin
        xyz="0 0 0"
        rpy="0 0 0" />
      <geometry>
        <mesh
          filename="package://Solid_URDF/meshes/Link_2.STL" />
      </geometry>
    </collision>
  </link>
  <joint
    name="Joint_2"
    type="revolute">
    <origin
      xyz="0 0 0"
      rpy="0 0 0" />
    <parent
      link="base_link" />
    <child
      link="Link_2" />
    <axis
      xyz="0 0 1" />
    <limit
      lower="0"
      upper="3.142"
      effort="300"
      velocity="3" />
  </joint>
  <link
    name="Link_3">
    <inertial>
      <origin
        xyz="-5.2042E-18 0.081267 -7.2272E-18"
        rpy="0 0 0" />
      <mass
        value="0.10048" />
      <inertia
        ixx="0.00020942"
        ixy="2.6655E-20"
        ixz="6.393E-12"
        iyy="1.4347E-05"
        iyz="1.4686E-20"
        izz="0.00020574" />
    </inertial>
    <visual>
      <origin
        xyz="0 0 0"
        rpy="0 0 0" />
      <geometry>
        <mesh
          filename="package://Solid_URDF/meshes/Link_3.STL" />
      </geometry>
      <material
        name="">
        <color
          rgba="0.79216 0.81961 0.93333 1" />
      </material>
    </visual>
    <collision>
      <origin
        xyz="0 0 0"
        rpy="0 0 0" />
      <geometry>
        <mesh
          filename="package://Solid_URDF/meshes/Link_3.STL" />
      </geometry>
    </collision>
  </link>
  <joint
    name="Joint_3"
    type="revolute">
    <origin
      xyz="0 0 0.07091"
      rpy="1.5708 0 0" />
    <parent
      link="Link_2" />
    <child
      link="Link_3" />
    <axis
      xyz="0 0 -1" />
    <limit
      lower="-1.57"
      upper="1.57"
      effort="200"
      velocity="3" />
  </joint>
  <link
    name="Link_4">
    <inertial>
      <origin
        xyz="-0.065014 -0.0125 -4.8132E-07"
        rpy="0 0 0" />
      <mass
        value="0.060766" />
      <inertia
        ixx="4.2232E-06"
        ixy="2.4803E-14"
        ixz="-1.0882E-09"
        iyy="0.00013388"
        iyz="8.1538E-12"
        izz="0.00013578" />
    </inertial>
    <visual>
      <origin
        xyz="0 0 0"
        rpy="0 0 0" />
      <geometry>
        <mesh
          filename="package://Solid_URDF/meshes/Link_4.STL" />
      </geometry>
      <material
        name="">
        <color
          rgba="0.79216 0.81961 0.93333 1" />
      </material>
    </visual>
    <collision>
      <origin
        xyz="0 0 0"
        rpy="0 0 0" />
      <geometry>
        <mesh
          filename="package://Solid_URDF/meshes/Link_4.STL" />
      </geometry>
    </collision>
  </link>
  <joint
    name="Joint_4"
    type="revolute">
    <origin
      xyz="0 0.1555 0"
      rpy="0 0 0" />
    <parent
      link="Link_3" />
    <child
      link="Link_4" />
    <axis
      xyz="0 0 1" />
    <limit
      lower="0"
      upper="3.142"
      effort="200"
      velocity="3" />
  </joint>
  <link
    name="Link_5">
    <inertial>
      <origin
        xyz="1.9965E-18 1.1102E-16 0.019929"
        rpy="0 0 0" />
      <mass
        value="0.046012" />
      <inertia
        ixx="9.1204E-06"
        ixy="-4.4171E-16"
        ixz="-8.9824E-22"
        iyy="1.0499E-05"
        iyz="8.8543E-22"
        izz="1.3863E-05" />
    </inertial>
    <visual>
      <origin
        xyz="0 0 0"
        rpy="0 0 0" />
      <geometry>
        <mesh
          filename="package://Solid_URDF/meshes/Link_5.STL" />
      </geometry>
      <material
        name="">
        <color
          rgba="0.79216 0.81961 0.93333 1" />
      </material>
    </visual>
    <collision>
      <origin
        xyz="0 0 0"
        rpy="0 0 0" />
      <geometry>
        <mesh
          filename="package://Solid_URDF/meshes/Link_5.STL" />
      </geometry>
    </collision>
  </link>
  <joint
    name="Joint_5"
    type="revolute">
    <origin
      xyz="-0.1483 -0.0125 0"
      rpy="3.1416 -1.5708 0" />
    <parent
      link="Link_4" />
    <child
      link="Link_5" />
    <axis
      xyz="0 0 1" />
    <limit
      lower="0"
      upper="3.142"
      effort="200"
      velocity="3" />
  </joint>
  <link
    name="Link_6">
    <inertial>
      <origin
        xyz="0.0039759 -0.0025 0.043169"
        rpy="0 0 0" />
      <mass
        value="0.0082022" />
      <inertia
        ixx="7.8318E-06"
        ixy="4.0409E-23"
        ixz="2.5719E-07"
        iyy="7.8154E-06"
        iyz="-1.4296E-21"
        izz="1.2643E-07" />
    </inertial>
    <visual>
      <origin
        xyz="0 0 0"
        rpy="0 0 0" />
      <geometry>
        <mesh
          filename="package://Solid_URDF/meshes/Link_6.STL" />
      </geometry>
      <material
        name="">
        <color
          rgba="0.79216 0.81961 0.93333 1" />
      </material>
    </visual>
    <collision>
      <origin
        xyz="0 0 0"
        rpy="0 0 0" />
      <geometry>
        <mesh
          filename="package://Solid_URDF/meshes/Link_6.STL" />
      </geometry>
    </collision>
  </link>
  <joint
    name="Joint_6"
    type="prismatic">
    <origin
      xyz="0 0.0025 0.038"
      rpy="0 0 0" />
    <parent
      link="Link_5" />
    <child
      link="Link_6" />
    <axis
      xyz="-1 0 0" />
    <limit
      lower="0"
      upper="0.03"
      effort="100"
      velocity="3" />
  </joint>
  <link
    name="Link_7">
    <inertial>
      <origin
        xyz="-0.0039759 -0.0025 0.043169"
        rpy="0 0 0" />
      <mass
        value="0.0082022" />
      <inertia
        ixx="7.8318E-06"
        ixy="-3.1846E-23"
        ixz="-2.5719E-07"
        iyy="7.8154E-06"
        iyz="-1.5325E-21"
        izz="1.2643E-07" />
    </inertial>
    <visual>
      <origin
        xyz="0 0 0"
        rpy="0 0 0" />
      <geometry>
        <mesh
          filename="package://Solid_URDF/meshes/Link_7.STL" />
      </geometry>
      <material
        name="">
        <color
          rgba="0.79216 0.81961 0.93333 1" />
      </material>
    </visual>
    <collision>
      <origin
        xyz="0 0 0"
        rpy="0 0 0" />
      <geometry>
        <mesh
          filename="package://Solid_URDF/meshes/Link_7.STL" />
      </geometry>
    </collision>
  </link>
  <joint
    name="Joint_7"
    type="prismatic">
    <origin
      xyz="0 0.0025 0.038"
      rpy="0 0 0" />
    <parent
      link="Link_5" />
    <child
      link="Link_7" />
    <axis
      xyz="-1 0 0" />
    <limit
      lower="-0.03"
      upper="0"
      effort="100"
      velocity="3" />
  </joint>
</robot>